<?xml version="1.0" ?>
<robot name="modulebot" xmlns:xacro="http://ros.org/wiki/xacro">
	<xacro:include filename="$(find description)/urdf/common_properties.xacro"/>

	<link name="base_footprint"/>

	<joint name="base_joint" type="fixed">
		<parent link="base_footprint"/>
		<child link="base_link"/>
		<origin xyz="0 0 0.142" rpy="0 0 0"/>
	</joint>

	<link name="base_link">
		<visual>
			<origin xyz="-0.225 -0.2 -0.142" rpy="1.57 0 1.57"/>
			<geometry>
				<mesh filename="package://description/meshes/base/body.stl" scale="0.001 0.001 0.001"/>
			</geometry>
			<material name="white"/>
		</visual>

		<collision>
			<origin xyz="0 0 0" rpy="0 0 0"/>
			<geometry>
				<box size="0.45 0.4 0.242"/>
			</geometry>
		</collision>
	</link>

	<joint name="wheel_left_joint" type="continuous">
		<parent link="base_link"/>
		<child link="wheel_left_link"/>
		<origin xyz="0.105 0.144 -0.07" rpy="0 0 0"/>
		<axis xyz="0 1 0"/>
	</joint>

	<link name="wheel_left_link">
		<visual>
			<origin xyz="0.0775 -0.0235 -0.0775" rpy="0 0 1.57"/>
			<geometry>
				<mesh filename="package://description/meshes/wheel/left_wheel.stl" scale="0.001 0.001 0.001"/>
			</geometry>
			<material name="black"/>
		</visual>

		<collision>
			<origin xyz="0 0 0" rpy="1.57 0 0"/>
			<geometry>
				<cylinder length="0.047" radius="0.0775"/>
			</geometry>
		</collision>
	</link>

	<joint name="wheel_right_joint" type="continuous">
		<parent link="base_link"/>
		<child link="wheel_right_link"/>
		<origin xyz="0.105 -0.144 -0.07" rpy="0 0 0"/>
		<axis xyz="0 1 0"/>
	</joint>

	<link name="wheel_right_link">
		<visual>
			<origin xyz="0.0775 -0.0235 -0.0775" rpy="0 0 1.57"/>
			<geometry>
				<mesh filename="package://description/meshes/wheel/right_wheel.stl" scale="0.001 0.001 0.001"/>
			</geometry>
			<material name="black"/>
		</visual>

		<collision>
			<origin xyz="0 0 0" rpy="1.57 0 0"/>
			<geometry>
				<cylinder length="0.047" radius="0.0775"/>
			</geometry>
		</collision>
	</link>

	<joint name="imu_joint" type="fixed">
		<parent link="base_link"/>
		<child link="imu_link"/>
		<origin xyz="0.107 0 -0.07" rpy="0 0 0"/>
	</joint>

	<link name="imu_link">
		<visual>
			<origin xyz="-0.0175 -0.0175 0.005" rpy="-1.57 0 0"/>
			<geometry>
				<mesh filename="package://description/meshes/sensor/imu.stl" scale="0.001 0.001 0.001"/>
			</geometry>
			<material name="blue"/>
		</visual>
	</link>

	<joint name="scan_joint" type="fixed">
		<parent link="base_link"/>
		<child link="base_scan"/>
		<origin xyz="0.072 0 0.045"/>
	</joint>

	<link name="base_scan">
		<visual>
			<origin xyz="0.066 0.0355 -0.03816" rpy="0 0 3.14"/>
			<geometry>
				<mesh filename="package://description/meshes/sensor/ydlidar.stl" scale="0.001 0.001 0.001"/>
			</geometry>
			<material name="blue"/>
		</visual>
	</link>

	<joint name="camera_joint" type="fixed">
		<parent link="base_link"/>
		<child link="camera_link"/>
		<origin xyz="0 0 0.893" rpy="0 0 0"/>
	</joint>

	<link name="camera_link">
		<visual>
			<origin xyz="-0.0125 -0.055 0" rpy="1.57 0 1.57"/>
			<geometry>
				<mesh filename="package://description/meshes/sensor/d435.stl" scale="0.001 0.001 0.001"/>
			</geometry>
			<material name="brown"/>
		</visual>
	</link>
</robot>